try:
    error()
finally:
    print "done"
