##  -*- python -*-  
# db file automatically generated by genconf on: Wed Jun 11 15:13:15 2008
## insulates outside world against anything bad that could happen
## also prevents global scope pollution
def _fillCfgDb():
    from GaudiKernel.Proxy.ConfigurableDb import CfgDb

    # get a handle on the repository of Configurables
    cfgDb = CfgDb()

    # populate the repository with informations on Configurables 

    cfgDb.add( configurable = 'PhysicalChannelsHist',
               package = 'L0',
               module  = 'L0.L0MuonMonitorConf',
               lib     = 'L0MuonMonitor' )
    cfgDb.add( configurable = 'LogicalPads2DMaps',
               package = 'L0',
               module  = 'L0.L0MuonMonitorConf',
               lib     = 'L0MuonMonitor' )
    cfgDb.add( configurable = 'L0MuonOnlineMonitor',
               package = 'L0',
               module  = 'L0.L0MuonMonitorConf',
               lib     = 'L0MuonMonitor' )
    cfgDb.add( configurable = 'L0MuonMonitor',
               package = 'L0',
               module  = 'L0.L0MuonMonitorConf',
               lib     = 'L0MuonMonitor' )
    cfgDb.add( configurable = 'L0MuonAlgComparison',
               package = 'L0',
               module  = 'L0.L0MuonMonitorConf',
               lib     = 'L0MuonMonitor' )
    cfgDb.add( configurable = 'InstantaneousRate',
               package = 'L0',
               module  = 'L0.L0MuonMonitorConf',
               lib     = 'L0MuonMonitor' )
    return #_fillCfgDb
# fill cfgDb at module import...
try:
    _fillCfgDb()
    #house cleaning...
    del _fillCfgDb
except Exception,err:
    print "Py:ConfigurableDb   ERROR Problem with [%s] content!" % __name__
    print "Py:ConfigurableDb   ERROR",err
    print "Py:ConfigurableDb   ERROR   ==> culprit is package [L0] !"
